<mujoco model="opendoge">
  <compiler angle="radian" meshdir="../meshes/" />

  <size njmax="500" nconmax="100" /><asset>
    <mesh name="base_link" file="base_link.STL" />
    <mesh name="FL_hip" file="FL_hip.STL" />
    <mesh name="FL_thigh" file="FL_thigh.STL" />
    <mesh name="FL_calf" file="FL_calf.STL" />
    <mesh name="FL_foot" file="FL_foot.STL" />
    <mesh name="FR_hip" file="FR_hip.STL" />
    <mesh name="FR_thigh" file="FR_thigh.STL" />
    <mesh name="FR_calf" file="FR_calf.STL" />
    <mesh name="FR_foot" file="FR_foot.STL" />
    <mesh name="RL_hip" file="RL_hip.STL" />
    <mesh name="RL_thigh" file="RL_thigh.STL" />
    <mesh name="RL_calf" file="RL_calf.STL" />
    <mesh name="RL_foot" file="RL_foot.STL" />
    <mesh name="RR_hip" file="RR_hip.STL" />
    <mesh name="RR_thigh" file="RR_thigh.STL" />
    <mesh name="RR_calf" file="RR_calf.STL" />
    <mesh name="RR_foot" file="RR_foot.STL" />
  </asset>

  <default><joint limited="true" damping="0.0" frictionloss="0.0" armature="0.005" /><geom contype="1" conaffinity="1" friction="1.0 0.05 0.05" solref="0.005 1" /></default><worldbody>
    <body name="robot" pos="0 0 0.30" quat="1 0 0 0"><joint name="float_base" type="free" limited="false" /><inertial pos="0.000134773648275938 1.36367968484041e-06 0.000770353067310358" mass="2.2352588780603" fullinertia="0.0054247 0.0099197 0.013453 1.29e-06 -9.59e-05 -2e-07" /><site name="imu" pos="0 0 0.03" /><geom type="mesh" rgba="0.792157 0.819608 0.933333 1" mesh="base_link" contype="0" conaffinity="0" group="1" />
    <body name="FL_hip" pos="0.1425 0.039989 0">
      <inertial pos="-0.0019419 -0.00069982 1.3745e-06" quat="-0.265811 0.655274 0.265304 0.655419" mass="0.27308" diaginertia="0.00010203 8.98057e-05 8.68843e-05" />
      <joint name="FL_hip_joint" pos="0 0 0" axis="1 0 0" range="-0.785 0.26" />
      <geom type="mesh" rgba="0.79216 0.81961 0.93333 1" mesh="FL_hip" />
      <body name="FL_thigh" pos="0 0.08615 0">
        <inertial pos="-0.0003843 -0.028095 -0.0056139" quat="0.928486 -0.246825 -0.101419 -0.258275" mass="0.344" diaginertia="0.000317783 0.00026653 0.000146627" />
        <joint name="FL_thigh_joint" pos="0 0 0" axis="0 1 0" range="-0.785 0.785" />
        <geom type="mesh" rgba="0.79216 0.81961 0.93333 1" mesh="FL_thigh" />
        <body name="FL_calf" pos="0 0 -0.1">
          <inertial pos="0.00411629 -1.00306e-05 -0.055478" quat="0.707144 0.0094899 0.00945321 0.706943" mass="0.0271166" diaginertia="3.96234e-05 3.90139e-05 1.42952e-06" />
          <joint name="FL_calf_joint" pos="0 0 0" axis="0 1 0" range="-2.68 -1.04" />
          <geom type="mesh" rgba="0.79216 0.81961 0.93333 1" mesh="FL_calf" />
          <geom pos="-1.19561e-05 0 -0.0993915" quat="1 0 0 0" type="mesh" rgba="1 1 1 1" mesh="FL_foot" />
        </body>
      </body>
    </body>
    <body name="FR_hip" pos="0.1425 -0.040075 0">
      <inertial pos="-0.0019419 0.00069983 1.3735e-06" quat="0.265811 0.655274 -0.265304 0.655419" mass="0.27308" diaginertia="0.00010203 8.98057e-05 8.68843e-05" />
      <joint name="FR_hip_joint" pos="0 0 0" axis="1 0 0" range="-0.26 0.785" />
      <geom type="mesh" rgba="0.79216 0.81961 0.93333 1" mesh="FR_hip" />
      <body name="FR_thigh" pos="0 -0.0861 0">
        <inertial pos="-0.00039283 0.028155 -0.0056112" quat="0.928391 0.247385 -0.101402 0.258085" mass="0.344" diaginertia="0.000317975 0.000266712 0.000146673" />
        <joint name="FR_thigh_joint" pos="0 0 0" axis="0 1 0" range="-0.785 0.785" />
        <geom type="mesh" rgba="0.79216 0.81961 0.93333 1" mesh="FR_thigh" />
        <body name="FR_calf" pos="0 0 -0.1">
          <inertial pos="0.00411628 -1.00305e-05 -0.0554782" quat="0.707144 0.00948983 0.00945314 0.706943" mass="0.0271168" diaginertia="3.96233e-05 3.90138e-05 1.42952e-06" />
          <joint name="FR_calf_joint" pos="0 0 0" axis="0 1 0" range="-2.68 -1.04" />
          <geom type="mesh" rgba="0.792157 0.819608 0.933333 1" mesh="FR_calf" />
          <geom pos="-1.19561e-05 0 -0.0993915" quat="1 0 0 0" type="mesh" rgba="1 1 1 1" mesh="FR_foot" />
        </body>
      </body>
    </body>
    <body name="RL_hip" pos="-0.1425 0.040025 0">
      <inertial pos="0.0019419 -0.00069983 1.3735e-06" quat="0.265304 0.655419 -0.265811 0.655274" mass="0.27308" diaginertia="0.00010203 8.98057e-05 8.68843e-05" />
      <joint name="RL_hip_joint" pos="0 0 0" axis="1 0 0" range="-0.785 0.26" />
      <geom type="mesh" rgba="0.79216 0.81961 0.93333 1" mesh="RL_hip" />
      <body name="RL_thigh" pos="0 0.08615 0">
        <inertial pos="-0.0003843 -0.028095 -0.0056139" quat="0.928486 -0.246825 -0.101419 -0.258275" mass="0.344" diaginertia="0.000317783 0.00026653 0.000146627" />
        <joint name="RL_thigh_joint" pos="0 0 0" axis="0 1 0" range="-0.785 0.785" />
        <geom type="mesh" rgba="0.79216 0.81961 0.93333 1" mesh="RL_thigh" />
        <body name="RL_calf" pos="0 0 -0.1">
          <inertial pos="0.00411629 -1.00306e-05 -0.055478" quat="0.707144 0.00948988 0.00945319 0.706943" mass="0.0271166" diaginertia="3.96234e-05 3.90139e-05 1.42952e-06" />
          <joint name="RL_calf_joint" pos="0 0 0" axis="0 1 0" range="-2.68 -1.04" />
          <geom type="mesh" rgba="0.79216 0.81961 0.93333 1" mesh="RL_calf" />
          <geom pos="-1.19561e-05 0 -0.0993915" quat="1 0 0 0" type="mesh" rgba="1 1 1 1" mesh="RL_foot" />
        </body>
      </body>
    </body>
    <body name="RR_hip" pos="-0.1425 -0.040025 0">
      <inertial pos="0.0019419 0.00069982 1.3745e-06" quat="-0.265304 0.655419 0.265811 0.655274" mass="0.27308" diaginertia="0.00010203 8.98057e-05 8.68843e-05" />
      <joint name="RR_hip_joint" pos="0 0 0" axis="1 0 0" range="-0.26 0.785" />
      <geom type="mesh" rgba="0.79216 0.81961 0.93333 1" mesh="RR_hip" />
      <body name="RR_thigh" pos="0 -0.08615 0">
        <inertial pos="-0.00039283 0.028155 -0.0056112" quat="0.928391 0.247385 -0.101402 0.258085" mass="0.344" diaginertia="0.000317975 0.000266712 0.000146673" />
        <joint name="RR_thigh_joint" pos="0 0 0" axis="0 1 0" range="-0.785 0.785" />
        <geom type="mesh" rgba="0.79216 0.81961 0.93333 1" mesh="RR_thigh" />
        <body name="RR_calf" pos="0 0 -0.1">
          <inertial pos="0.00411629 -1.00306e-05 -0.055478" quat="0.707144 0.00948988 0.00945319 0.706943" mass="0.0271166" diaginertia="3.96234e-05 3.90139e-05 1.42952e-06" />
          <joint name="RR_calf_joint" pos="0 0 0" axis="0 1 0" range="-2.68 -1.04" />
          <geom type="mesh" rgba="0.79216 0.81961 0.93333 1" mesh="RR_calf" />
          <geom pos="-1.19561e-05 0 -0.0993915" quat="1 0 0 0" type="mesh" rgba="1 1 1 1" mesh="RR_foot" />
        </body>
      </body>
    </body>
  </body></worldbody>
<actuator><motor name="FL_hip_joint" joint="FL_hip_joint" gear="1" ctrllimited="true" ctrlrange="-6 6" /><motor name="FL_thigh_joint" joint="FL_thigh_joint" gear="1" ctrllimited="true" ctrlrange="-6 6" /><motor name="FL_calf_joint" joint="FL_calf_joint" gear="1" ctrllimited="true" ctrlrange="-9 9" /><motor name="FR_hip_joint" joint="FR_hip_joint" gear="1" ctrllimited="true" ctrlrange="-6 6" /><motor name="FR_thigh_joint" joint="FR_thigh_joint" gear="1" ctrllimited="true" ctrlrange="-6 6" /><motor name="FR_calf_joint" joint="FR_calf_joint" gear="1" ctrllimited="true" ctrlrange="-9 9" /><motor name="RL_hip_joint" joint="RL_hip_joint" gear="1" ctrllimited="true" ctrlrange="-6 6" /><motor name="RL_thigh_joint" joint="RL_thigh_joint" gear="1" ctrllimited="true" ctrlrange="-6 6" /><motor name="RL_calf_joint" joint="RL_calf_joint" gear="1" ctrllimited="true" ctrlrange="-9 9" /><motor name="RR_hip_joint" joint="RR_hip_joint" gear="1" ctrllimited="true" ctrlrange="-6 6" /><motor name="RR_thigh_joint" joint="RR_thigh_joint" gear="1" ctrllimited="true" ctrlrange="-6 6" /><motor name="RR_calf_joint" joint="RR_calf_joint" gear="1" ctrllimited="true" ctrlrange="-9 9" /></actuator><sensor><framequat name="orientation" objtype="site" objname="imu" noise="0.001" /><framepos name="position" objtype="site" objname="imu" noise="0.001" /><gyro name="angular-velocity" site="imu" noise="0.005" cutoff="34.9" /><velocimeter name="linear-velocity" site="imu" noise="0.001" cutoff="30" /><accelerometer name="linear-acceleration" site="imu" noise="0.005" cutoff="157" /></sensor></mujoco>