<mujoco model="uika">
    <compiler angle="radian" meshdir="/home/saiki/IsaacGym/HTDW4438_HIMloco/resources/robots/uika/meshes/" />
    <size njmax="500" nconmax="100" />

    <asset>
        <mesh name="base" file="base_simple.STL" />
        <mesh name="FL_hip" file="FL_hip.STL" />
        <mesh name="FL_thigh" file="FL_thigh.STL" />
        <mesh name="FL_calf" file="FL_calf.STL" />
        <mesh name="FL_foot" file="FL_foot.STL" />
        <mesh name="FR_hip" file="FR_hip.STL" />
        <mesh name="FR_thigh" file="FR_thigh.STL" />
        <mesh name="FR_calf" file="FR_calf.STL" />
        <mesh name="FR_foot" file="FR_foot.STL" />
        <mesh name="RL_hip" file="RL_hip.STL" />
        <mesh name="RL_thigh" file="RL_thigh.STL" />
        <mesh name="RL_calf" file="RL_calf.STL" />
        <mesh name="RL_foot" file="RL_foot.STL" />
        <mesh name="RR_hip" file="RR_hip.STL" />
        <mesh name="RR_thigh" file="RR_thigh.STL" />
        <mesh name="RR_calf" file="RR_calf.STL" />
        <mesh name="RR_foot" file="RR_foot.STL" />
    </asset>

    <default>
        <joint limited="true" damping="0.1" frictionloss="0.0" armature="0.005"/>
        <geom contype="1" conaffinity="1" friction="0.8 0.05 0.05" solref="0.005 1"/>
    </default>

    <worldbody>
        <body name="robot" pos="0 0 0.35" quat="1 0 0 0">
            <joint name="float_base" type="free" limited="false"/>
            <inertial pos="0.0993589953258177 -0.000347868138743462 -0.0602742254852854" mass="6.09961854" diaginertia="0.02511856 0.07600646 0.08133534"/>
            <site name="imu" pos="0 0 0" />
            <geom type="mesh" contype="0" conaffinity="0" group="1" rgba="0.898 0.917 0.929 1" mesh="base" />

            <!-- Front Left Leg -->
            <body name="fl_hip" pos="0.153 0.06 -0.06">
                <inertial pos="0.0415030017853425 0.00817193653082768 0.00860885998023001" mass="0.93308959" diaginertia="0.00115759 0.00110208 0.00110642"/>
                <joint name="FL_hip_joint" pos="0 0 0" axis="1 0 0" limited="true" range="-1.5 0" />
                <geom type="mesh" contype="0" conaffinity="0" group="1" rgba="0.898 0.917 0.929 1" mesh="FL_hip" />

                <body name="fl_thigh" pos="0.0560002942624635 0.0483946520428511 0.0470555828957988">
                    <inertial pos="-0.0535775244580455 0.0350832915184582 -0.0163587879417473" mass="0.47644935" diaginertia="0.00108325 0.00222936 0.00221100"/>
                    <joint name="FL_thigh_joint" pos="0 0 0" axis="0 0.716968137917879 0.697105938298167" limited="true" range="-0.785 0.785" />
                    <geom type="mesh" contype="0" conaffinity="0" group="1" rgba="0.776 0.757 0.737 1" mesh="FL_thigh" />

                    <body name="fl_calf" pos="-0.152475747348646 0.109582492974347 -0.07397319848129">
                        <inertial pos="0.0700291670932001 -0.015965855611679 -0.00222776798959823" mass="0.14745425" diaginertia="0.00002268 0.00073677 0.00073626"/>
                        <joint name="FL_calf_joint" pos="0 0 0" axis="0 0.716968137917877 0.69710593829817" limited="true" range="0.1 1.11" />
                        <geom type="mesh" contype="0" conaffinity="0" group="1" rgba="0.776 0.757 0.737 1" mesh="FL_calf" />

                        <!-- Foot as geom (no separate body, fixed to calf) -->
                        <geom type="mesh" pos="0.211725899509592 -0.00252783551179853 -0.0167659233263265" contype="1" conaffinity="1" rgba="0.298 0.298 0.298 1" mesh="FL_foot" />
                        <site name="FL_foot_site" pos="0.211725899509592 -0.00252783551179853 -0.0167659233263265" size="0.01" rgba="0 0 1 0.5"/>
                    </body>
                </body>
            </body>

            <!-- Front Right Leg -->
            <body name="fr_hip" pos="0.153 -0.06 -0.06">
                <inertial pos="0.0416078227711511 -0.0104146438294053 0.0101964785626593" mass="0.93308959" diaginertia="0.00114451 0.00106757 0.00112221"/>
                <joint name="FR_hip_joint" pos="0 0 0" axis="1 0 0" limited="true" range="0 1.5" />
                <geom type="mesh" contype="0" conaffinity="0" group="1" rgba="0.898 0.917 0.929 1" mesh="FR_hip" />

                <body name="fr_thigh" pos="0.0560001425520644 -0.0483952686957443 0.047054585042635">
                    <inertial pos="-0.0547142990756392 -0.0356584537936173 -0.0169064776984609" mass="0.48074554" diaginertia="0.00111780 0.00231794 0.00230119"/>
                    <joint name="FR_thigh_joint" pos="0 0 0" axis="0 -0.716968137917902 0.697105938298144" limited="true" range="-0.785 0.785" />
                    <geom type="mesh" contype="0" conaffinity="0" group="1" rgba="0.898 0.917 0.929 1" mesh="FR_thigh" />

                    <body name="fr_calf" pos="-0.152475581141278 -0.109581813299707 -0.0739724994411187">
                        <inertial pos="0.0700291670951076 0.0159658555227684 -0.0022277679039307" mass="0.14745425" diaginertia="0.00002268 0.00073677 0.00073626"/>
                        <joint name="FR_calf_joint" pos="0 0 0" axis="0 -0.716968137917903 0.697105938298144" limited="true" range="-1.11 -0.1" />
                        <geom type="mesh" contype="0" conaffinity="0" group="1" rgba="0.776 0.757 0.737 1" mesh="FR_calf" />

                        <geom type="mesh" pos="0.211725899509592 0.00252783231169756 -0.0167659202148746" contype="1" conaffinity="1" rgba="0.298 0.298 0.298 1" mesh="FR_foot" />
                        <site name="FR_foot_site" pos="0.211725899509592 0.00252783231169756 -0.0167659202148746" size="0.01" rgba="0 0 1 0.5"/>
                    </body>
                </body>
            </body>

            <!-- Rear Left Leg -->
            <body name="rl_hip" pos="-0.153 0.06 -0.06">
                <inertial pos="-0.0415758519890377 0.0101366668291682 0.0104818480714982" mass="0.93308959" diaginertia="0.00113963 0.00109432 0.00109594"/>
                <joint name="RL_hip_joint" pos="0 0 0" axis="-1 0 0" limited="true" range="0 1.5" />
                <geom type="mesh" contype="0" conaffinity="0" group="1" rgba="0.898 0.917 0.929 1" mesh="RL_hip" />

                <body name="rl_thigh" pos="-0.0559996912405691 0.0483949903212994 0.0470544297768458">
                    <inertial pos="-0.0547144667121707 0.0356782468970246 -0.0168886153666892" mass="0.48074554" diaginertia="0.00111780 0.00231683 0.00230230"/>
                    <joint name="RL_thigh_joint" pos="0 0 0" axis="0 0.716968137917878 0.697105938298169" limited="true" range="-0.785 0.785" />
                    <geom type="mesh" contype="0" conaffinity="0" group="1" rgba="0.898 0.917 0.929 1" mesh="RL_thigh" />

                    <body name="rl_calf" pos="-0.152475747348643 0.109582492974347 -0.0739731984812923">
                        <inertial pos="0.0700291670931948 -0.0159658556116849 -0.00222776798959213" mass="0.14745425" diaginertia="0.00002268 0.00073677 0.00073626"/>
                        <joint name="RL_calf_joint" pos="0 0 0" axis="0 0.716968137917874 0.697105938298173" limited="true" range="0.1 1.11" />
                        <geom type="mesh" contype="0" conaffinity="0" group="1" rgba="0.776 0.757 0.737 1" mesh="RL_calf" />

                        <geom type="mesh" pos="0.211725899509589 -0.00252783551179986 -0.0167659233263231" contype="1" conaffinity="1" rgba="0.298 0.298 0.298 1" mesh="RL_foot" />
                        <site name="RL_foot_site" pos="0.211725899509589 -0.00252783551179986 -0.0167659233263231" size="0.01" rgba="0 0 1 0.5"/>
                    </body>
                </body>
            </body>

            <!-- Rear Right Leg -->
            <body name="rr_hip" pos="-0.153 -0.06 -0.06">
                <inertial pos="-0.0416445343568521 -0.010769761078396 0.00983207310486511" mass="0.93308959" diaginertia="0.00114349 0.00108600 0.00110242"/>
                <joint name="RR_hip_joint" pos="0 0 0" axis="-1 0 0" limited="true" range="-1.5 0" />
                <geom type="mesh" contype="0" conaffinity="0" group="1" rgba="0.898 0.917 0.929 1" mesh="RR_hip" />

                <body name="rr_thigh" pos="-0.0559998574479382 -0.0483962427296829 0.0470544132941808">
                    <inertial pos="-0.0547143122112738 -0.0356584597048889 -0.0169064837781644" mass="0.48074554" diaginertia="0.00111780 0.00231794 0.00230119"/>
                    <joint name="RR_thigh_joint" pos="0 0 0" axis="0 -0.716968137917902 0.697105938298144" limited="true" range="-0.785 0.785" />
                    <geom type="mesh" contype="0" conaffinity="0" group="1" rgba="0.898 0.917 0.929 1" mesh="RR_thigh" />

                    <body name="rr_calf" pos="-0.152475581141278 -0.109581813299707 -0.0739724994411164">
                        <inertial pos="0.0700291670951063 0.0159658555227615 -0.0022277679039392" mass="0.14745425" diaginertia="0.00002268 0.00073677 0.00073626"/>
                        <joint name="RR_calf_joint" pos="0 0 0" axis="0 -0.716968137917903 0.697105938298143" limited="true" range="-1.11 -0.1" />
                        <geom type="mesh" contype="0" conaffinity="0" group="1" rgba="0.776 0.757 0.737 1" mesh="RR_calf" />

                        <geom type="mesh" pos="0.211725899509593 0.00252783231169423 -0.0167659202148782" contype="1" conaffinity="1" rgba="0.298 0.298 0.298 1" mesh="RR_foot" />
                        <site name="RR_foot_site" pos="0.211725899509593 0.00252783231169423 -0.0167659202148782" size="0.01" rgba="0 0 1 0.5"/>
                    </body>
                </body>
            </body>
        </body>
    </worldbody>

    <actuator>
        <motor name="FL_hip_joint" joint="FL_hip_joint" gear="1" ctrllimited="true" ctrlrange="-10 10"/>
        <motor name="FL_thigh_joint" joint="FL_thigh_joint" gear="1" ctrllimited="true" ctrlrange="-10 10"/>
        <motor name="FL_calf_joint" joint="FL_calf_joint" gear="1" ctrllimited="true" ctrlrange="-10 10"/>
        <motor name="FR_hip_joint" joint="FR_hip_joint" gear="1" ctrllimited="true" ctrlrange="-10 10"/>
        <motor name="FR_thigh_joint" joint="FR_thigh_joint" gear="1" ctrllimited="true" ctrlrange="-10 10"/>
        <motor name="FR_calf_joint" joint="FR_calf_joint" gear="1" ctrllimited="true" ctrlrange="-10 10"/>
        <motor name="RL_hip_joint" joint="RL_hip_joint" gear="1" ctrllimited="true" ctrlrange="-10 10"/>
        <motor name="RL_thigh_joint" joint="RL_thigh_joint" gear="1" ctrllimited="true" ctrlrange="-10 10"/>
        <motor name="RL_calf_joint" joint="RL_calf_joint" gear="1" ctrllimited="true" ctrlrange="-10 10"/>
        <motor name="RR_hip_joint" joint="RR_hip_joint" gear="1" ctrllimited="true" ctrlrange="-10 10"/>
        <motor name="RR_thigh_joint" joint="RR_thigh_joint" gear="1" ctrllimited="true" ctrlrange="-10 10"/>
        <motor name="RR_calf_joint" joint="RR_calf_joint" gear="1" ctrllimited="true" ctrlrange="-10 10"/>
    </actuator>

    <sensor>
        <actuatorpos name='FL_hip_joint_p'  actuator='FL_hip_joint' user='13'/>
        <actuatorpos name='FL_thigh_joint_p'  actuator='FL_thigh_joint' user='13'/>
        <actuatorpos name='FL_calf_joint_p'  actuator='FL_calf_joint' user='13'/>
        <actuatorpos name='FR_hip_joint_p'  actuator='FR_hip_joint' user='13'/>
        <actuatorpos name='FR_thigh_joint_p'  actuator='FR_thigh_joint' user='13'/>
        <actuatorpos name='FR_calf_joint_p'  actuator='FR_calf_joint' user='13'/>
        <actuatorpos name='RL_hip_joint_p'  actuator='RL_hip_joint' user='13'/>
        <actuatorpos name='RL_thigh_joint_p'  actuator='RL_thigh_joint' user='13'/>
        <actuatorpos name='RL_calf_joint_p'  actuator='RL_calf_joint' user='13'/>
        <actuatorpos name='RR_hip_joint_p'  actuator='RR_hip_joint' user='13'/>
        <actuatorpos name='RR_thigh_joint_p'  actuator='RR_thigh_joint' user='13'/>
        <actuatorpos name='RR_calf_joint_p'  actuator='RR_calf_joint' user='13'/>
        <actuatorvel name='FL_hip_joint_v'  actuator='FL_hip_joint' user='13'/>
        <actuatorvel name='FL_thigh_joint_v'  actuator='FL_thigh_joint' user='13'/>
        <actuatorvel name='FL_calf_joint_v'  actuator='FL_calf_joint' user='13'/>
        <actuatorvel name='FR_hip_joint_v'  actuator='FR_hip_joint' user='13'/>
        <actuatorvel name='FR_thigh_joint_v'  actuator='FR_thigh_joint' user='13'/>
        <actuatorvel name='FR_calf_joint_v'  actuator='FR_calf_joint' user='13'/>
        <actuatorvel name='RL_hip_joint_v'  actuator='RL_hip_joint' user='13'/>
        <actuatorvel name='RL_thigh_joint_v'  actuator='RL_thigh_joint' user='13'/>
        <actuatorvel name='RL_calf_joint_v'  actuator='RL_calf_joint' user='13'/>
        <actuatorvel name='RR_hip_joint_v'  actuator='RR_hip_joint' user='13'/>
        <actuatorvel name='RR_thigh_joint_v'  actuator='RR_thigh_joint' user='13'/>
        <actuatorvel name='RR_calf_joint_v'  actuator='RR_calf_joint' user='13'/>
        <actuatorfrc name='FL_hip_joint_f'  actuator='FL_hip_joint'  user='13' noise='1e-3'/>
        <actuatorfrc name='FL_thigh_joint_f'  actuator='FL_thigh_joint'  user='13' noise='1e-3'/>
        <actuatorfrc name='FL_calf_joint_f'  actuator='FL_calf_joint'  user='13' noise='1e-3'/>
        <actuatorfrc name='FR_hip_joint_f'  actuator='FR_hip_joint'  user='13' noise='1e-3'/>
        <actuatorfrc name='FR_thigh_joint_f'  actuator='FR_thigh_joint'  user='13' noise='1e-3'/>
        <actuatorfrc name='FR_calf_joint_f'  actuator='FR_calf_joint'  user='13' noise='1e-3'/>
        <actuatorfrc name='RL_hip_joint_f'  actuator='RL_hip_joint'  user='13' noise='1e-3'/>
        <actuatorfrc name='RL_thigh_joint_f'  actuator='RL_thigh_joint'  user='13' noise='1e-3'/>
        <actuatorfrc name='RL_calf_joint_f'  actuator='RL_calf_joint'  user='13' noise='1e-3'/>
        <actuatorfrc name='RR_hip_joint_f'  actuator='RR_hip_joint'  user='13' noise='1e-3'/>
        <actuatorfrc name='RR_thigh_joint_f'  actuator='RR_thigh_joint'  user='13' noise='1e-3'/>
        <actuatorfrc name='RR_calf_joint_f'  actuator='RR_calf_joint'  user='13' noise='1e-3'/>
        <framequat     name='orientation' objtype='site' noise='0.001' objname='imu'/>
        <framepos      name='position' objtype='site' noise='0.001' objname='imu'/>
        <gyro          name='angular-velocity'    site='imu' noise='0.005' cutoff='34.9'/>
        <velocimeter   name='linear-velocity'     site='imu' noise='0.001' cutoff='30'/>
        <accelerometer name='linear-acceleration' site='imu' noise='0.005' cutoff='157'/>
    </sensor>
</mujoco>
