<?xml version="1.0" encoding="utf-8"?>
<!-- 四足机器人URDF主文件 | 名称：htdw_4438 | 命名：fl前左/fr前右/rl后左/rr后右 | 肢体：hip髋/thigh大腿/calf小腿/foot脚 | 关节：revolute旋转/fixed固定 -->
<robot name="htdw_4438">
  <mujoco>
    <compiler 
      meshdir="../meshes" 
      balanceinertia="true" 
      discardvisual="false" />
  </mujoco>
  <!-- 全局复用材质：白色不透明 -->
  <material name="white_material">
    <color rgba="1 1 1 1" />
  </material>

  <!-- 基座连杆：机器人核心躯干 -->
  <link name="base_link">
    <inertial>
      <origin xyz="-0.00139370 0.00012462 0.01353999" rpy="0 0 0" />
      <mass value="2.68214792" />
      <inertia ixx="0.00676934" ixy="-0.00002413" ixz="0.00027724" iyy="0.01195702" iyz="0.00003879" izz="0.01215361" />
    </inertial>
    <visual>
      <origin xyz="0 0 0" rpy="0 0 0" />
      <geometry>
        <mesh filename="../meshes/base_link_simple.STL" />
      </geometry>
      <material name="white_material" />
    </visual>
    <collision>
      <origin xyz="0 0 0.025" rpy="0 0 0" />
      <geometry>
        <box size="0.17 0.09 0.138" />
      </geometry>
    </collision>
  </link>

  <!-- 前左腿FL - 髋部：连杆+关节（基座→前左髋） -->
  <link name="fl_hip">
    <inertial>
      <origin xyz="0.03269580 0.00444394  -0.00009507" rpy="0 0 0" />
      <mass value="0.29235822" />
      <inertia ixx="0.00008921" ixy="-0.00004438" ixz="0.00000113" iyy="0.00040664" iyz="0.00000010" izz="0.00040549" />
    </inertial>
    <visual>
      <origin xyz="0 0 0" rpy="0 0 0" />
      <geometry>
        <mesh filename="../meshes/FL_hip.STL" />
      </geometry>
      <material name="white_material" />
    </visual>
    <collision>
      <origin xyz="0.035 0 0" rpy="1.56 1.56 0" />
      <geometry>
        <cylinder length="0.045" radius="0.03" />
      </geometry>
    </collision>
  </link>
  <joint name="fl_hip_joint" type="revolute">
    <origin xyz="0.0909 0.04 0" rpy="0 0 0" />
    <parent link="base_link" />
    <child link="fl_hip" />
    <axis xyz="1 0 0" />
    <limit lower="-0.9" upper="0.9" effort="10" velocity="9.95" initial="0"/>
  </joint>

  <!-- 前左腿FL - 大腿：连杆+关节（前左髋→前左大腿） -->
  <link name="fl_thigh">
    <inertial>
      <origin xyz="-0.00137569 0.03790927 -0.01165342" rpy="0 0 0" />
      <mass value="0.41040818" />
      <inertia ixx="0.00122480" ixy="0.00003407" ixz="-0.00003634" iyy="0.00056530" iyz="0.00028736" izz="0.00079023" />
    </inertial>
    <visual>
      <origin xyz="0 0 0" rpy="0 0 0" />
      <geometry>
        <mesh filename="../meshes/FL_thigh.STL" />
      </geometry>
      <material name="white_material" />
    </visual>
    <collision>
      <origin xyz="0.004 0.06 -0.045" rpy="0 0.35 0" />
      <geometry>
        <box size="0.02 0.025 0.10" />
      </geometry>
    </collision>
  </link>
  <joint name="fl_thigh_joint" type="revolute">
    <origin xyz="0.034 0.0254 0" rpy="0 0 0" />
    <parent link="fl_hip" />
    <child link="fl_thigh" />
    <axis xyz="0 1 0" />
    <limit lower="-1.5" upper="3.5" effort="10" velocity="9.95" initial="0.9"/>
  </joint>

  <!-- 前左腿FL - 小腿：连杆+关节（前左大腿→前左小腿） -->
  <link name="fl_calf">
    <inertial>
      <origin xyz="0.01082722 -0.00011477 -0.05285719" rpy="0 0 0" />
      <mass value="0.04033111" />
      <inertia ixx="0.00017694" ixy="0.00000005" ixz="0.00002974" iyy="0.00018413" iyz="0.00000004" izz="0.00000842" />
    </inertial>
    <visual>
      <origin xyz="0 0 0" rpy="0 0 0" />
      <geometry>
        <mesh filename="../meshes/FL_calf.STL" />
      </geometry>
      <material name="white_material" />
    </visual>
    <collision>
      <origin xyz="0.013 0 -0.05" rpy="0 -0.2 0" />
      <geometry>
        <cylinder length="0.1" radius="0.01" />
      </geometry>
    </collision>
  </link>
  <joint name="fl_calf_joint" type="revolute">
    <origin xyz="0 0.0604 -0.12" rpy="0 0 0" />
    <parent link="fl_thigh" />
    <child link="fl_calf" />
    <axis xyz="0 1 0" />
    <limit lower="-2.5" upper="-1.2" effort="10" velocity="9.95" initial="-1.8"/>
  </joint>

  <!-- 前左腿FL - 脚部：连杆+固定关节（前左小腿→前左脚） -->
  <link name="fl_foot">
    <inertial>
      <origin xyz="0.00384334 -0.00065935 0.01540433" rpy="0 0 0" />
      <mass value="0.00657865" />
      <inertia ixx="0.00000202" ixy="0.00000003" ixz="-0.00000043" iyy="0.00000222" iyz="0.00000009" izz="0.00000049" />
    </inertial>
    <visual>
      <origin xyz="0 0 0" rpy="0 0 0" />
      <geometry>
        <mesh filename="../meshes/FL_foot.STL" />
      </geometry>
      <material name="white_material" />
    </visual>
    <collision>
      <origin xyz="0.0025 0 0.0127" rpy="0 0 0" />
      <geometry>
        <sphere radius="0.015" />
      </geometry>
    </collision>
  </link>
  <joint name="fl_foot_joint" type="fixed" dont_collapse="true">
    <origin xyz="0.00206 0.00006 -0.13694" rpy="0 0 0" />
    <parent link="fl_calf" />
    <child link="fl_foot" />
  </joint>

  <!-- 前右腿FR - 髋部：连杆+关节（基座→前右髋） -->
  <link name="fr_hip">
    <inertial>
      <origin xyz="0.03269580 -0.00444394 0.00009507" rpy="0 0 0" />
      <mass value="0.29235822" />
      <inertia ixx="0.00008921" ixy="0.00004438" ixz="-0.00000113" iyy="0.00040664" iyz="0.00000010" izz="0.00040549" />
    </inertial>
    <visual>
      <origin xyz="0 0 0" rpy="0 0 0" />
      <geometry>
        <mesh filename="../meshes/FR_hip.STL" />
      </geometry>
      <material name="white_material" />
    </visual>
    <collision>
      <origin xyz="0.035 0 0" rpy="1.56 1.56 0" />
      <geometry>
        <cylinder length="0.045" radius="0.03" />
      </geometry>
    </collision>
  </link>
  <joint name="fr_hip_joint" type="revolute">
    <origin xyz="0.0909 -0.04 0" rpy="0 0 0" />
    <parent link="base_link" />
    <child link="fr_hip" />
    <axis xyz="1 0 0" />
    <limit lower="-0.9" upper="0.9" effort="10" velocity="9.95" initial="0.0"/>
  </joint>

  <!-- 前右腿FR - 大腿：连杆+关节（前右髋→前右大腿） -->
  <link name="fr_thigh">
    <inertial>
      <origin xyz="-0.00130371 -0.03791280 -0.01155686" rpy="0 0 0" />
      <mass value="0.41040818" />
      <inertia ixx="0.00122504" ixy="-0.00003226" ixz="-0.00003331" iyy="0.00056452" iyz="-0.00028624" izz="0.00078957" />
    </inertial>
    <visual>
      <origin xyz="0 0 0" rpy="0 0 0" />
      <geometry>
        <mesh filename="../meshes/FR_thigh.STL" />
      </geometry>
      <material name="white_material" />
    </visual>
    <collision>
      <origin xyz="0.004 -0.06 -0.045" rpy="0 0.35 0" />
      <geometry>
        <box size="0.02 0.025 0.10" />
      </geometry>
    </collision>
  </link>
  <joint name="fr_thigh_joint" type="revolute">
    <origin xyz="0.034 -0.0254 0" rpy="0 0 0" />
    <parent link="fr_hip" />
    <child link="fr_thigh" />
    <axis xyz="0 1 0" />
    <limit lower="-1.5" upper="3.5" effort="10" velocity="9.95" initial="0.9"/>
  </joint>

  <!-- 前右腿FR - 小腿：连杆+关节（前右大腿→前右小腿） -->
  <link name="fr_calf">
    <inertial>
      <origin xyz="0.01085394 0.00011547 -0.05299045" rpy="0 0 0" />
      <mass value="0.04033111" />
      <inertia ixx="0.00017737" ixy="-0.00000005" ixz="0.00002982" iyy="0.00018459" iyz="-0.00000004" izz="0.00000843" />
    </inertial>
    <visual>
      <origin xyz="0 0 0" rpy="0 0 0" />
      <geometry>
        <mesh filename="../meshes/FR_calf.STL" />
      </geometry>
      <material name="white_material" />
    </visual>
    <collision>
      <origin xyz="0.013 0 -0.05" rpy="0 -0.2 0" />
      <geometry>
        <cylinder length="0.1" radius="0.01" />
      </geometry>
    </collision>
  </link>
  <joint name="fr_calf_joint" type="revolute">
    <origin xyz="0 -0.0604 -0.12" rpy="0 0 0" />
    <parent link="fr_thigh" />
    <child link="fr_calf" />
    <axis xyz="0 1 0" />
    <limit lower="-2.5" upper="-1.2" effort="10" velocity="9.95" initial="-1.8"/>
  </joint>

  <!-- 前右腿FR - 脚部：连杆+固定关节（前右小腿→前右脚） -->
  <link name="fr_foot">
    <inertial>
      <origin xyz="0.00384334 -0.00065935 0.01540433" rpy="0 0 0" />
      <mass value="0.00657865" />
      <inertia ixx="0.00000202" ixy="0.00000003" ixz="-0.00000043" iyy="0.00000222" iyz="0.00000009" izz="0.00000049" />
    </inertial>
    <visual>
      <origin xyz="0 0 0" rpy="0 0 0" />
      <geometry>
        <mesh filename="../meshes/FR_foot.STL" />
      </geometry>
      <material name="white_material" />
    </visual>
    <collision>
      <origin xyz="0.0025 0 0.0127" rpy="0 0 0" />
      <geometry>
        <sphere radius="0.015" />
      </geometry>
    </collision>
  </link>
  <joint name="fr_foot_joint" type="fixed" dont_collapse="true">
    <origin xyz="0.00206 0.00006 -0.13694" rpy="0 0 0" />
    <parent link="fr_calf" />
    <child link="fr_foot" />
  </joint>

  <!-- 后左腿RL - 髋部：连杆+关节（基座→后左髋） -->
  <link name="rl_hip">
    <inertial>
      <origin xyz="-0.03269580 0.00444394 0.00009507" rpy="0 0 0" />
      <mass value="0.29235822" />
      <inertia ixx="0.00008921" ixy="0.00004438" ixz="0.00000113" iyy="0.00040664" iyz="-0.00000010" izz="0.00040549" />
    </inertial>
    <visual>
      <origin xyz="0 0 0" rpy="0 0 0" />
      <geometry>
        <mesh filename="../meshes/RL_hip.STL" />
      </geometry>
      <material name="white_material" />
    </visual>
    <collision>
      <origin xyz="-0.035 0 0" rpy="1.56 1.56 0" />
      <geometry>
        <cylinder length="0.045" radius="0.03" />
      </geometry>
    </collision>
  </link>
  <joint name="rl_hip_joint" type="revolute">
    <origin xyz="-0.0909 0.04 0" rpy="0 0 0" />
    <parent link="base_link" />
    <child link="rl_hip" />
    <axis xyz="1 0 0" />
    <limit lower="-0.9" upper="0.9" effort="10" velocity="9.95" initial="0"/>
  </joint>

  <!-- 后左腿RL - 大腿：连杆+关节（后左髋→后左大腿） -->
  <link name="rl_thigh">
    <inertial>
      <origin xyz="-0.00137569 0.03790927 -0.01165342" rpy="0 0 0" />
      <mass value="0.41040818" />
      <inertia ixx="0.00122480" ixy="0.00003407" ixz="-0.00003634" iyy="0.00056530" iyz="0.00028736" izz="0.00079023" />
    </inertial>
    <visual>
      <origin xyz="0 0 0" rpy="0 0 0" />
      <geometry>
        <mesh filename="../meshes/RL_thigh.STL" />
      </geometry>
      <material name="white_material" />
    </visual>
    <collision>
      <origin xyz="0.004 0.06 -0.045" rpy="0 0.35 0" />
      <geometry>
        <box size="0.02 0.025 0.10" />
      </geometry>
    </collision>
  </link>
  <joint name="rl_thigh_joint" type="revolute">
    <origin xyz="-0.034 0.0254 0" rpy="0 0 0" />
    <parent link="rl_hip" />
    <child link="rl_thigh" />
    <axis xyz="0 1 0" />
    <limit lower="-1.5" upper="3.5" effort="10" velocity="9.95" initial="0.9"/>
  </joint>

  <!-- 后左腿RL - 小腿：连杆+关节（后左大腿→后左小腿） -->
  <link name="rl_calf">
    <inertial>
      <origin xyz="0.01082722 -0.00011477 -0.05285719" rpy="0 0 0" />
      <mass value="0.04033111" />
      <inertia ixx="0.00017694" ixy="0.00000005" ixz="0.00002974" iyy="0.00018413" iyz="0.00000004" izz="0.00000842" />
    </inertial>
    <visual>
      <origin xyz="0 0 0" rpy="0 0 0" />
      <geometry>
        <mesh filename="../meshes/RL_calf.STL" />
      </geometry>
      <material name="white_material" />
    </visual>
    <collision>
      <origin xyz="0.013 0 -0.05" rpy="0 -0.2 0" />
      <geometry>
        <cylinder length="0.1" radius="0.01" />
      </geometry>
    </collision>
  </link>
  <joint name="rl_calf_joint" type="revolute">
    <origin xyz="0 0.0604 -0.12" rpy="0 0 0" />
    <parent link="rl_thigh" />
    <child link="rl_calf" />
    <axis xyz="0 1 0" />
    <limit lower="-2.5" upper="-1.2" effort="10" velocity="9.95" initial="-1.8"/>
  </joint>

  <!-- 后左腿RL - 脚部：连杆+固定关节（后左小腿→后左脚） -->
  <link name="rl_foot">
    <inertial>
      <origin xyz="0.00384334 -0.00065935 0.01540433" rpy="0 0 0" />
      <mass value="0.00657865" />
      <inertia ixx="0.00000202" ixy="0.00000003" ixz="-0.00000043" iyy="0.00000222" iyz="0.00000009" izz="0.00000049" />
    </inertial>
    <visual>
      <origin xyz="0 0 0" rpy="0 0 0" />
      <geometry>
        <mesh filename="../meshes/RL_foot.STL" />
      </geometry>
      <material name="white_material" />
    </visual>
    <collision>
      <origin xyz="0.0025 0 0.0127" rpy="0 0 0" />
      <geometry>
        <sphere radius="0.015" />
      </geometry>
    </collision>
  </link>
  <joint name="rl_foot_joint" type="fixed" dont_collapse="true">
    <origin xyz="-0.00206 0.00006 -0.13694" rpy="0 0 0" />
    <parent link="rl_calf" />
    <child link="rl_foot" />
  </joint>

  <!-- 后右腿RR - 髋部：连杆+关节（基座→后右髋） -->
  <link name="rr_hip">
    <inertial>
      <origin xyz="-0.03269580 -0.00444394 -0.00009507" rpy="0 0 0" />
      <mass value="0.29235822" />
      <inertia ixx="0.00008921" ixy="-0.00004438" ixz="-0.00000113" iyy="0.00040664" iyz="-0.00000010" izz="0.00040549" />
    </inertial>
    <visual>
      <origin xyz="0 0 0" rpy="0 0 0" />
      <geometry>
        <mesh filename="../meshes/RR_hip.STL" />
      </geometry>
      <material name="white_material" />
    </visual>
    <collision>
      <origin xyz="-0.035 0 0" rpy="1.56 1.56 0" />
      <geometry>
        <cylinder length="0.045" radius="0.03" />
      </geometry>
    </collision>
  </link>
  <joint name="rr_hip_joint" type="revolute">
    <origin xyz="-0.0909 -0.04 0" rpy="0 0 0" />
    <parent link="base_link" />
    <child link="rr_hip" />
    <axis xyz="1 0 0" />
    <limit lower="-0.9" upper="0.9" effort="10" velocity="9.95" initial="0"/>
  </joint>

  <!-- 后右腿RR - 大腿：连杆+关节（后右髋→后右大腿） -->
  <link name="rr_thigh">
    <inertial>
      <origin xyz="-0.00130371 -0.03791280 -0.01155686" rpy="0 0 0" />
      <mass value="0.41040818" />
      <inertia ixx="0.00122504" ixy="-0.00003226" ixz="-0.00003331" iyy="0.00056452" iyz="-0.00028624" izz="0.00078957" />
    </inertial>
    <visual>
      <origin xyz="0 0 0" rpy="0 0 0" />
      <geometry>
        <mesh filename="../meshes/RR_thigh.STL" />
      </geometry>
      <material name="white_material" />
    </visual>
    <collision>
      <origin xyz="0.004 -0.06 -0.045" rpy="0 0.35 0" />
      <geometry>
        <box size="0.02 0.025 0.10" />
      </geometry>
    </collision>
  </link>
  <joint name="rr_thigh_joint" type="revolute">
    <origin xyz="-0.034 -0.0254 0" rpy="0 0 0" />
    <parent link="rr_hip" />
    <child link="rr_thigh" />
    <axis xyz="0 1 0" />
    <limit lower="-1.5" upper="3.5" effort="10" velocity="9.95" initial="0.9"/>
  </joint>

  <!-- 后右腿RR - 小腿：连杆+关节（后右大腿→后右小腿） -->
  <link name="rr_calf">
    <inertial>
      <origin xyz="0.01085394 0.00011547 -0.05299045" rpy="0 0 0" />
      <mass value="0.04033111" />
      <inertia ixx="0.00017737" ixy="-0.00000005" ixz="0.00002982" iyy="0.00018459" iyz="-0.00000004" izz="0.00000843" />
    </inertial>
    <visual>
      <origin xyz="0 0 0" rpy="0 0 0" />
      <geometry>
        <mesh filename="../meshes/RR_calf.STL" />
      </geometry>
      <material name="white_material" />
    </visual>
    <collision>
      <origin xyz="0.013 0 -0.05" rpy="0 -0.2 0" />
      <geometry>
        <cylinder length="0.1" radius="0.01" />
      </geometry>
    </collision>
  </link>
  <joint name="rr_calf_joint" type="revolute">
    <origin xyz="0 -0.0604 -0.12" rpy="0 0 0" />
    <parent link="rr_thigh" />
    <child link="rr_calf" />
    <axis xyz="0 1 0" />
    <limit lower="-2.5" upper="-1.2" effort="10" velocity="9.95" initial="-1.8"/>
  </joint>

  <!-- 后右腿RR - 脚部：连杆+固定关节（后右小腿→后右脚） -->
  <link name="rr_foot">
    <inertial>
      <origin xyz="0.00384334 -0.00065935 0.01540433" rpy="0 0 0" />
      <mass value="0.00657865" />
      <inertia ixx="0.00000202" ixy="0.00000003" ixz="-0.00000043" iyy="0.00000222" iyz="0.00000009" izz="0.00000049" />
    </inertial>
    <visual>
      <origin xyz="0 0 0" rpy="0 0 0" />
      <geometry>
        <mesh filename="../meshes/RR_foot.STL" />
      </geometry>
      <material name="white_material" />
    </visual>
    <collision>
      <origin xyz="0.0025 0 0.0127" rpy="0 0 0" />
      <geometry>
        <sphere radius="0.015" />
      </geometry>
    </collision>
  </link>
  <joint name="rr_foot_joint" type="fixed" dont_collapse="true">
    <origin xyz="-0.00206 0.00006 -0.13694" rpy="0 0 0" />
    <parent link="rr_calf" />
    <child link="rr_foot" />
  </joint>

</robot>
